{"e": "depthUpdate", "E": 1703936451333, "T": 1703936451329, "s": "ETHUSDT", "U": 3743827045045, "u": 3743827048488, "pu": 3743827044911, "b": [["500.00", "184.422"], ["1000.00", "127.045"], ["2058.66", "0.616"], ["2264.53", "15.142"], ["2275.35", "0.478"], ["2276.84", "1.048"], ["2276.86", "0.059"], ["2279.42", "1.186"], ["2281.97", "2.951"], ["2281.98", "0.238"], ["2284.81", "13.526"], ["2284.82", "1.428"], ["2285.04", "1.906"], ["2285.05", "3.400"], ["2285.27", "6.608"], ["2285.28", "14.331"], ["2285.50", "74.587"], ["2285.51", "12.041"], ["2285.73", "1.450"], ["2285.74", "45.150"], ["2285.94", "2.868"], ["2285.96", "2.557"], ["2286.19", "1.200"], ["2286.41", "7.023"], ["2286.42", "1.200"], ["2286.64", "1.527"], ["2286.65", "21.279"], ["2286.87", "23.652"], ["2286.88", "23.404"], ["2286.97", "18.535"], ["2287.01", "7.286"], ["2287.40", "132.845"]], "a": [["2287.57", "0.000"], ["2287.59", "0.000"], ["2287.63", "7.593"], ["2287.72", "0.000"], ["2287.75", "2.018"], ["2287.91", "1.241"], ["2287.96", "5.659"], ["2288.00", "5.603"], ["2288.10", "14.235"], ["2288.23", "49.394"], ["2288.26", "8.557"], ["2288.79", "1.546"], ["2288.97", "157.654"], ["2289.01", "4.372"], ["2289.04", "3.786"], ["2289.30", "5.514"], ["2289.53", "45.712"], ["2292.34", "1.504"], ["2292.36", "0.506"], ["2294.92", "4.174"], ["2297.47", "1.471"], ["2297.48", "0.020"], ["2401.76", "0.010"]]}
{"e": "depthUpdate", "E": 1703936451437, "T": 1703936451407, "s": "ETHUSDT", "U": 3743827048795, "u": 3743827051263, "pu": 3743827048488, "b": [["500.00", "184.422"], ["2173.03", "0.960"], ["2285.94", "2.868"], ["2286.58", "1.374"], ["2286.62", "22.905"], ["2286.64", "2.401"], ["2286.73", "2.104"], ["2287.01", "24.708"], ["2287.40", "132.879"]], "a": [["2287.65", "0.000"], ["2287.75", "2.527"], ["2288.07", "18.983"], ["2288.10", "17.235"], ["2288.15", "45.287"], ["2288.30", "7.770"], ["2288.38", "11.161"], ["2288.53", "2.919"], ["2288.61", "0.600"], ["2288.66", "0.027"], ["2288.69", "1.833"], ["2288.76", "25.815"], ["2288.84", "22.402"], ["2288.97", "0.239"], ["2288.99", "166.540"], ["2289.07", "3.607"], ["2289.21", "9.134"], ["2289.29", "0.600"], ["2289.44", "2.554"], ["2289.52", "13.388"], ["2289.67", "4.373"], ["2289.75", "0.853"], ["2289.85", "0.000"], ["2289.90", "3.661"], ["2289.98", "0.812"], ["2290.13", "0.462"], ["2290.15", "15.041"], ["2290.21", "0.800"], ["2290.54", "289.247"], ["2291.93", "40.928"], ["2292.26", "225.501"], ["2292.27", "10.000"], ["2292.28", "36.076"], ["2292.29", "92.145"], ["2298.84", "0.000"], ["2324.72", "0.000"], ["2326.30", "30.054"], ["2378.89", "0.965"], ["2378.90", "56.016"]]}
{"e": "depthUpdate", "E": 1703936451543, "T": 1703936451539, "s": "ETHUSDT", "U": 3743827051983, "u": 3743827054689, "pu": 3743827051263, "b": [["500.00", "184.422"], ["1000.00", "127.045"], ["1143.70", "0.000"], ["2173.03", "0.917"], ["2264.53", "15.142"], ["2284.54", "9.386"], ["2284.59", "0.000"], ["2284.86", "1.009"], ["2285.02", "3.186"], ["2285.05", "1.400"], ["2285.09", "5.396"], ["2285.24", "5.977"], ["2285.29", "35.210"], ["2285.32", "15.227"], ["2285.55", "0.900"], ["2285.78", "3.619"], ["2285.94", "2.586"], ["2285.95", "0.282"], ["2286.00", "44.579"], ["2286.05", "7.968"], ["2286.23", "8.744"], ["2286.34", "0.921"], ["2286.35", "72.502"], ["2286.46", "43.929"], ["2286.69", "1.444"], ["2286.92", "2.567"], ["2287.40", "143.604"]], "a": [["2287.75", "2.503"], ["2288.06", "23.622"], ["2288.07", "19.183"], ["2288.08", "4.085"], ["2288.16", "5.311"], ["2288.20", "4.863"], ["2288.22", "30.505"], ["2288.29", "18.258"], ["2288.30", "7.970"], ["2288.31", "1.947"], ["2288.33", "4.596"], ["2288.39", "24.859"], ["2288.43", "17.718"], ["2288.45", "13.484"], ["2288.52", "2.668"], ["2288.53", "3.119"], ["2288.54", "5.300"], ["2288.62", "2.611"], ["2288.66", "0.227"], ["2288.67", "1.327"], ["2288.75", "0.452"], ["2288.76", "26.015"], ["2288.77", "10.782"], ["2288.85", "1.446"], ["2288.89", "1.000"], ["2288.90", "11.194"], ["2288.97", "0.439"], ["2288.98", "1.056"], ["2289.00", "8.724"], ["2289.08", "1.024"], ["2289.12", "12.504"], ["2289.13", "0.820"], ["2289.20", "3.136"], ["2289.21", "9.334"], ["2289.22", "15.996"], ["2289.29", "0.600"], ["2289.31", "27.364"], ["2289.35", "3.620"], ["2289.36", "5.031"], ["2289.43", "80.403"], ["2289.44", "2.754"], ["2289.45", "1.227"], ["2289.53", "45.712"], ["2289.54", "2.042"], ["2289.57", "6.091"], ["2289.59", "13.404"], ["2289.66", "0.600"], ["2289.67", "4.573"], ["2289.68", "1.015"], ["2289.77", "4.332"], ["2289.80", "122.175"], ["2289.82", "1.039"], ["2289.89", "1.931"], ["2289.90", "3.861"], ["2289.91", "3.096"], ["2290.00", "20.323"], ["2290.03", "0.210"], ["2290.04", "0.059"], ["2290.05", "0.890"], ["2290.12", "1.270"], ["2290.13", "0.662"], ["2290.14", "0.800"], ["2290.22", "2.808"], ["2290.26", "0.209"], ["2290.28", "0.713"], ["2298.84", "0.965"], ["2365.46", "0.020"], ["2378.89", "0.000"]]}
{"e": "depthUpdate", "E": 1703936451645, "T": 1703936451624, "s": "ETHUSDT", "U": 3743827054795, "u": 3743827057038, "pu": 3743827054689, "b": [["500.00", "184.422"], ["1000.01", "0.000"], ["2173.03", "0.960"], ["2228.93", "0.000"], ["2264.53", "15.142"], ["2275.97", "1.086"], ["2283.19", "1.610"], ["2284.63", "17.672"], ["2284.78", "0.000"], ["2284.86", "0.809"], ["2285.02", "12.286"], ["2285.09", "5.196"], ["2285.24", "71.616"], ["2285.25", "30.331"], ["2285.31", "46.834"], ["2285.54", "27.276"], ["2285.71", "75.601"], ["2285.77", "31.930"], ["2285.95", "0.282"], ["2286.00", "44.379"], ["2286.03", "7.166"], ["2286.05", "9.968"], ["2286.23", "8.544"], ["2286.46", "43.729"], ["2286.58", "2.686"], ["2286.69", "1.244"], ["2286.72", "29.339"], ["2286.73", "0.792"], ["2286.91", "9.648"], ["2287.01", "7.286"], ["2287.04", "1.318"], ["2287.24", "0.366"]], "a": [["2287.41", "15.956"], ["2287.63", "1.593"], ["2287.67", "6.024"], ["2287.75", "0.018"], ["2287.77", "4.630"], ["2287.86", "0.000"], ["2287.91", "1.241"], ["2287.96", "5.551"], ["2288.05", "5.304"], ["2288.06", "23.422"], ["2288.10", "14.235"], ["2288.26", "8.292"], ["2288.28", "12.290"], ["2288.29", "18.058"], ["2288.30", "25.450"], ["2288.32", "0.015"], ["2288.39", "24.859"], ["2288.51", "0.409"], ["2288.52", "2.468"], ["2288.74", "0.409"], ["2288.75", "0.252"], ["2288.94", "46.539"], ["2288.97", "0.639"], ["2288.98", "0.856"], ["2289.19", "3.996"], ["2289.21", "9.134"], ["2289.39", "23.398"], ["2289.42", "14.436"], ["2289.43", "80.203"], ["2289.65", "6.346"], ["2289.66", "0.400"], ["2289.88", "25.971"], ["2289.89", "1.731"], ["2289.94", "2.285"], ["2290.04", "19.369"], ["2290.06", "66.356"], ["2290.11", "0.552"], ["2290.12", "1.070"], ["2290.15", "12.813"], ["2298.84", "0.000"], ["2310.28", "0.531"], ["2324.00", "39.146"], ["2324.01", "0.487"]]}
{"e": "depthUpdate", "E": 1703936451747, "T": 1703936451741, "s": "ETHUSDT", "U": 3743827057374, "u": 3743827059740, "pu": 3743827057038, "b": [["500.00", "184.422"], ["2173.03", "0.917"], ["2266.85", "0.599"], ["2266.86", "1.641"], ["2275.97", "0.051"], ["2283.41", "13.016"], ["2283.45", "0.000"], ["2283.47", "12.208"], ["2284.71", "1.156"], ["2284.85", "1.191"], ["2284.86", "0.809"], ["2285.08", "14.874"], ["2285.09", "5.196"], ["2285.14", "0.568"], ["2285.24", "5.977"], ["2285.31", "46.634"], ["2285.32", "15.227"], ["2285.43", "12.269"], ["2285.49", "0.819"], ["2285.54", "26.876"], ["2285.55", "1.100"], ["2285.70", "68.811"], ["2285.77", "31.530"], ["2285.78", "3.819"], ["2285.95", "0.282"], ["2285.96", "2.419"], ["2285.99", "10.716"], ["2286.00", "44.179"], ["2286.01", "24.041"], ["2286.05", "7.968"], ["2286.22", "3.804"], ["2286.23", "8.544"], ["2286.45", "51.677"], ["2286.46", "43.729"], ["2286.68", "1.594"], ["2286.69", "1.244"], ["2286.81", "31.668"], ["2286.83", "1.503"], ["2286.91", "9.448"], ["2286.92", "2.567"], ["2287.05", "1.523"]], "a": [["2287.63", "3.989"], ["2287.66", "13.959"], ["2287.75", "0.374"], ["2287.98", "4.971"], ["2288.07", "18.983"], ["2288.26", "8.557"], ["2288.28", "12.025"], ["2288.30", "25.250"], ["2288.53", "2.919"], ["2288.76", "25.815"], ["2288.99", "166.340"], ["2289.22", "15.796"], ["2289.45", "1.027"], ["2289.68", "0.815"], ["2289.91", "2.896"], ["2290.06", "0.856"], ["2290.14", "0.600"], ["2290.17", "0.538"], ["2290.54", "288.794"], ["2290.90", "20.748"], ["2291.63", "1.789"], ["2292.45", "0.643"], ["2321.71", "0.038"], ["2365.81", "0.011"]]}
{"e": "depthUpdate", "E": 1703936451848, "T": 1703936451846, "s": "ETHUSDT", "U": 3743827059913, "u": 3743827062852, "pu": 3743827059740, "b": [["500.00", "184.422"], ["1000.00", "127.045"], ["2012.92", "0.187"], ["2173.03", "0.960"], ["2187.54", "0.059"], ["2228.61", "9.017"], ["2264.53", "15.142"], ["2266.85", "0.590"], ["2266.86", "0.606"], ["2275.97", "1.086"], ["2282.58", "1.706"], ["2282.99", "113.896"], ["2283.41", "23.016"], ["2283.45", "36.000"], ["2283.47", "48.208"], ["2283.67", "0.874"], ["2284.86", "1.009"], ["2285.02", "10.286"], ["2285.09", "5.396"], ["2285.24", "71.616"], ["2285.25", "15.370"], ["2285.26", "6.031"], ["2285.31", "46.834"], ["2285.54", "27.076"], ["2285.70", "66.811"], ["2285.77", "31.730"], ["2285.93", "9.852"], ["2285.95", "0.282"], ["2286.00", "44.379"], ["2286.23", "8.744"], ["2286.46", "43.929"], ["2286.67", "25.196"], ["2286.69", "1.444"], ["2286.72", "7.474"], ["2286.76", "26.703"], ["2286.81", "31.842"], ["2286.83", "1.329"], ["2286.91", "9.648"], ["2287.02", "24.443"], ["2287.04", "4.799"], ["2287.19", "0.153"], ["2287.22", "6.654"], ["2287.30", "6.761"], ["2287.40", "143.616"]], "a": [["2287.41", "6.556"], ["2287.60", "0.009"], ["2287.65", "0.000"], ["2287.66", "0.790"], ["2287.67", "6.295"], ["2287.75", "0.454"], ["2287.91", "0.804"], ["2287.98", "1.971"], ["2288.06", "23.622"], ["2288.08", "4.085"], ["2288.10", "14.235"], ["2288.13", "2.565"], ["2288.15", "23.436"], ["2288.17", "3.946"], ["2288.19", "22.315"], ["2288.21", "7.157"], ["2288.22", "26.285"], ["2288.29", "18.258"], ["2288.30", "3.591"], ["2288.32", "21.674"], ["2288.39", "24.959"], ["2288.43", "11.572"], ["2288.46", "95.587"], ["2288.47", "17.490"], ["2288.52", "2.668"], ["2288.57", "0.970"], ["2288.75", "0.452"], ["2288.98", "1.056"], ["2288.99", "8.925"], ["2289.02", "27.945"], ["2289.06", "159.119"], ["2289.21", "9.334"], ["2289.44", "2.954"], ["2289.48", "1.028"], ["2289.67", "4.773"], ["2289.90", "4.061"], ["2290.04", "0.059"], ["2290.06", "66.356"], ["2290.12", "1.270"], ["2290.27", "3.174"], ["2290.40", "3.376"], ["2291.88", "5.734"], ["2292.34", "114.925"], ["2298.84", "0.965"], ["2324.00", "38.181"]]}
{"e": "depthUpdate", "E": 1703936451949, "T": 1703936451946, "s": "ETHUSDT", "U": 3743827062892, "u": 3743827065970, "pu": 3743827062852, "b": [["500.00", "184.422"], ["2195.91", "0.054"], ["2244.40", "0.224"], ["2254.95", "1.271"], ["2254.96", "0.000"], ["2264.53", "15.142"], ["2265.51", "1.196"], ["2265.53", "0.041"], ["2285.02", "12.286"], ["2285.11", "0.018"], ["2285.21", "0.903"], ["2285.26", "4.031"], ["2285.69", "1.796"], ["2285.95", "0.282"], ["2286.26", "4.641"], ["2286.60", "6.192"], ["2286.67", "18.638"], ["2286.81", "31.668"], ["2286.83", "1.503"], ["2287.02", "21.164"], ["2287.05", "0.439"], ["2287.06", "0.680"], ["2287.13", "18.411"], ["2287.29", "1.270"]], "a": [["2287.63", "0.768"], ["2287.67", "4.953"], ["2287.69", "6.280"], ["2287.75", "0.018"], ["2287.98", "1.863"], ["2288.05", "5.412"], ["2288.22", "30.506"], ["2288.25", "17.542"], ["2288.26", "8.292"], ["2288.30", "3.856"], ["2288.32", "4.194"], ["2288.37", "18.599"], ["2288.39", "24.859"], ["2288.94", "1.825"], ["2289.05", "160.898"], ["2289.06", "0.600"], ["2289.70", "5.809"], ["2290.52", "4.983"], ["2292.27", "10.000"], ["2292.28", "36.076"], ["2292.29", "92.145"], ["2308.59", "0.116"], ["2319.17", "0.201"], ["2329.72", "126.101"], ["2329.73", "0.011"]]}
{"e": "depthUpdate", "E": 1703936452053, "T": 1703936452041, "s": "ETHUSDT", "U": 3743827066174, "u": 3743827068662, "pu": 3743827065970, "b": [["500.00", "184.422"], ["1000.00", "127.045"], ["2173.03", "0.917"], ["2266.68", "0.018"], ["2276.36", "0.099"], ["2284.83", "19.490"], ["2285.02", "12.286"], ["2285.06", "40.193"], ["2285.26", "4.031"], ["2285.28", "14.131"], ["2285.29", "35.610"], ["2285.51", "12.041"], ["2285.52", "0.215"], ["2285.69", "3.796"], ["2285.74", "45.150"], ["2285.75", "0.605"], ["2285.93", "7.852"], ["2285.95", "0.282"], ["2285.97", "4.213"], ["2285.98", "1.328"], ["2286.20", "15.321"], ["2286.43", "33.840"], ["2286.57", "34.452"], ["2286.66", "30.075"], ["2286.73", "22.656"], ["2286.76", "4.839"], ["2286.88", "23.204"], ["2286.89", "7.869"], ["2286.98", "2.515"]], "a": [["2287.63", "1.411"], ["2287.68", "13.676"], ["2287.69", "0.280"], ["2287.75", "0.227"], ["2288.08", "3.885"], ["2288.30", "3.656"], ["2288.41", "5.474"], ["2288.53", "2.719"], ["2288.76", "25.615"], ["2288.77", "10.882"], ["2288.99", "8.725"], ["2289.22", "15.596"], ["2289.45", "0.827"], ["2289.68", "0.615"], ["2289.91", "2.696"], ["2290.14", "0.400"], ["2361.78", "0.000"]]}
{"e": "depthUpdate", "E": 1703936452161, "T": 1703936452161, "s": "ETHUSDT", "U": 3743827069129, "u": 3743827071384, "pu": 3743827068662, "b": [["500.00", "184.422"], ["1143.70", "0.043"], ["2264.53", "15.142"], ["2276.57", "0.017"], ["2284.82", "1.228"], ["2285.05", "1.200"], ["2285.28", "13.931"], ["2285.51", "11.841"], ["2285.74", "44.950"], ["2285.95", "0.000"], ["2285.97", "4.013"], ["2286.19", "1.000"], ["2286.42", "1.000"], ["2286.65", "21.079"], ["2286.71", "11.677"], ["2286.88", "23.004"], ["2287.02", "21.165"], ["2287.40", "143.714"]], "a": [["2287.41", "15.956"], ["2287.60", "4.211"], ["2287.75", "0.317"], ["2287.91", "0.804"], ["2288.06", "23.822"], ["2288.25", "21.721"], ["2288.28", "12.025"], ["2288.29", "18.458"], ["2288.32", "0.015"], ["2288.39", "31.005"], ["2288.41", "5.496"], ["2288.42", "21.915"], ["2288.46", "89.441"], ["2288.52", "2.868"], ["2288.75", "0.652"], ["2288.98", "1.256"], ["2289.02", "187.059"], ["2289.04", "3.786"], ["2289.05", "2.379"], ["2289.21", "9.534"], ["2289.29", "0.809"], ["2289.44", "3.154"], ["2289.53", "45.503"], ["2289.67", "4.973"], ["2289.90", "4.261"], ["2290.12", "1.470"], ["2298.24", "0.065"], ["2401.76", "0.053"]]}
{"e": "depthUpdate", "E": 1703936452263, "T": 1703936452263, "s": "ETHUSDT", "U": 3743827071399, "u": 3743827073428, "pu": 3743827071384, "b": [["500.00", "184.422"], ["1000.00", "127.045"], ["1143.70", "0.000"], ["2058.66", "0.616"], ["2213.94", "0.146"], ["2232.07", "0.000"], ["2250.17", "0.139"], ["2264.53", "15.142"], ["2266.69", "67.110"], ["2266.85", "0.599"], ["2271.98", "0.249"], ["2275.76", "0.019"], ["2276.57", "80.017"], ["2279.53", "0.170"], ["2283.41", "13.016"], ["2283.45", "0.000"], ["2283.47", "12.208"], ["2284.16", "70.612"], ["2284.17", "0.697"], ["2285.02", "10.286"], ["2285.29", "37.610"], ["2285.41", "4.021"], ["2285.42", "62.167"], ["2285.95", "0.000"], ["2286.26", "4.599"], ["2286.40", "7.155"], ["2286.41", "5.310"], ["2286.57", "34.474"], ["2286.60", "6.324"], ["2287.02", "7.796"], ["2287.05", "1.523"], ["2287.13", "17.327"], ["2287.19", "6.798"], ["2287.22", "0.009"], ["2287.40", "143.732"]], "a": [["2287.62", "2.252"], ["2287.63", "6.000"], ["2287.64", "2.630"], ["2287.65", "5.465"], ["2287.66", "0.790"], ["2287.67", "0.295"], ["2287.68", "7.676"], ["2287.72", "2.000"], ["2287.75", "0.018"], ["2287.77", "2.630"], ["2287.98", "1.971"], ["2288.05", "5.304"], ["2288.25", "17.807"], ["2288.27", "3.698"], ["2288.29", "22.637"], ["2288.30", "3.391"], ["2288.39", "24.859"], ["2288.43", "17.718"], ["2288.77", "10.782"], ["2288.83", "31.831"], ["2289.02", "35.072"], ["2289.04", "162.900"], ["2289.42", "11.489"], ["2289.43", "78.492"], ["2290.40", "5.087"], ["2290.41", "11.540"], ["2290.73", "0.000"], ["2290.91", "7.922"], ["2291.66", "6.938"], ["2291.67", "1.922"], ["2292.06", "16.261"], ["2293.95", "0.330"], ["2295.13", "0.367"], ["2298.24", "80.065"], ["2298.90", "0.554"], ["2298.92", "0.072"], ["2302.67", "4.916"], ["2302.69", "3.714"], ["2325.01", "0.124"], ["2325.03", "0.252"], ["2343.13", "0.124"], ["2343.15", "0.230"], ["2361.26", "0.022"], ["2361.29", "16.980"], ["2401.76", "0.010"]]}
{"e": "depthUpdate", "E": 1703936452366, "T": 1703936452363, "s": "ETHUSDT", "U": 3743827073483, "u": 3743827075932, "pu": 3743827073428, "b": [["500.00", "184.422"], ["1000.00", "127.045"], ["2173.03", "0.917"], ["2251.12", "0.057"], ["2256.00", "289.226"], ["2264.53", "15.142"], ["2266.85", "0.590"], ["2271.97", "0.170"], ["2275.76", "0.189"], ["2277.78", "3.724"], ["2277.80", "25.969"], ["2277.90", "0.095"], ["2277.92", "0.057"], ["2280.05", "0.117"], ["2280.07", "0.000"], ["2280.17", "114.915"], ["2280.19", "0.284"], ["2282.32", "0.147"], ["2282.44", "0.061"], ["2283.41", "23.016"], ["2283.45", "36.000"], ["2283.47", "48.208"], ["2285.95", "0.282"], ["2287.01", "10.767"], ["2287.02", "5.804"], ["2287.04", "1.318"], ["2287.40", "143.942"]], "a": [["2287.41", "10.956"], ["2287.72", "0.000"], ["2287.75", "2.526"], ["2291.72", "0.561"], ["2291.73", "40.289"], ["2292.02", "0.430"], ["2292.80", "0.787"], ["2292.82", "0.000"], ["2293.99", "0.237"], ["2294.01", "0.273"], ["2295.07", "2.600"], ["2295.09", "34.553"], ["2296.26", "0.510"], ["2296.28", "0.122"], ["2297.34", "0.087"], ["2361.24", "1.069"], ["2378.90", "56.016"], ["2802.92", "0.000"]]}
{"e": "depthUpdate", "E": 1703936452468, "T": 1703936452468, "s": "ETHUSDT", "U": 3743827076032, "u": 3743827079586, "pu": 3743827075932, "b": [["500.00", "184.422"], ["1000.00", "127.195"], ["2256.22", "16.203"], ["2266.85", "0.599"], ["2284.86", "0.809"], ["2284.87", "1.739"], ["2285.09", "5.196"], ["2285.10", "0.229"], ["2285.32", "15.227"], ["2285.55", "1.100"], ["2285.78", "3.819"], ["2285.93", "7.195"], ["2285.95", "0.000"], ["2286.01", "24.041"], ["2286.23", "8.544"], ["2286.24", "7.977"], ["2286.46", "43.729"], ["2286.47", "1.074"], ["2286.69", "1.244"], ["2286.70", "19.179"], ["2286.92", "2.567"], ["2287.39", "22.313"], ["2287.40", "144.150"]], "a": [["2287.63", "0.000"], ["2287.64", "2.630"], ["2287.65", "0.000"], ["2287.67", "6.295"], ["2287.75", "0.430"], ["2287.77", "4.630"], ["2287.91", "0.804"], ["2287.98", "1.863"], ["2288.02", "13.484"], ["2288.25", "17.542"], ["2288.27", "3.963"], ["2289.02", "194.186"], ["2289.04", "3.786"], ["2290.25", "9.868"], ["2290.47", "2.119"], ["2291.79", "0.104"], ["2292.27", "0.000"], ["2292.28", "0.076"], ["2292.29", "56.145"]]}
{"e": "depthUpdate", "E": 1703936452571, "T": 1703936452570, "s": "ETHUSDT", "U": 3743827079670, "u": 3743827082435, "pu": 3743827079586, "b": [["500.00", "184.422"], ["1000.00", "127.045"], ["2250.80", "12.219"], ["2264.53", "15.142"], ["2266.69", "68.829"], ["2266.70", "0.061"], ["2266.80", "28.755"], ["2270.90", "27.688"], ["2272.50", "0.166"], ["2275.00", "237.597"], ["2275.97", "1.086"], ["2276.60", "0.539"], ["2280.70", "146.716"], ["2284.02", "1.939"], ["2284.03", "5.787"], ["2284.43", "0.000"], ["2285.39", "5.475"], ["2285.40", "0.190"], ["2285.74", "44.715"], ["2285.95", "0.282"], ["2286.26", "6.178"], ["2286.27", "2.207"], ["2286.49", "0.000"], ["2286.52", "17.700"], ["2286.83", "1.594"], ["2286.95", "0.138"], ["2287.02", "3.742"], ["2287.05", "0.439"], ["2287.39", "22.230"], ["2287.40", "144.731"]], "a": [["2287.41", "10.944"], ["2287.75", "0.018"], ["2288.17", "25.797"], ["2288.19", "0.464"], ["2288.32", "17.495"], ["2288.37", "1.120"], ["2288.58", "0.827"], ["2289.36", "6.608"], ["2289.37", "2.548"], ["2290.23", "5.869"], ["2290.24", "0.708"], ["2291.60", "3.334"], ["2291.61", "60.000"], ["2292.28", "10.076"], ["2292.30", "84.370"], ["2375.45", "0.097"], ["2401.76", "0.010"], ["2594.71", "0.000"]]}
{"e": "depthUpdate", "E": 1703936452673, "T": 1703936452669, "s": "ETHUSDT", "U": 3743827082470, "u": 3743827085903, "pu": 3743827082435, "b": [["500.00", "184.422"], ["2173.03", "0.960"], ["2264.53", "15.142"], ["2278.11", "4.069"], ["2284.22", "0.083"], ["2284.43", "0.219"], ["2284.79", "0.012"], ["2285.06", "38.193"], ["2285.24", "5.977"], ["2285.25", "81.008"], ["2285.29", "35.610"], ["2285.30", "25.565"], ["2285.32", "0.717"], ["2285.57", "0.000"], ["2285.69", "1.796"], ["2285.78", "1.819"], ["2285.86", "3.456"], ["2285.95", "0.000"], ["2285.98", "1.183"], ["2286.13", "14.990"], ["2286.28", "0.388"], ["2286.29", "66.264"], ["2286.32", "22.382"], ["2286.35", "8.556"], ["2287.02", "3.742"], ["2287.09", "1.084"], ["2287.39", "22.133"], ["2287.40", "144.741"]], "a": [["2287.41", "6.748"], ["2287.60", "0.009"], ["2287.62", "0.768"], ["2287.67", "4.953"], ["2287.69", "6.280"], ["2287.75", "0.432"], ["2288.02", "13.376"], ["2288.05", "5.412"], ["2288.23", "49.194"], ["2288.27", "3.698"], ["2288.29", "22.811"], ["2288.45", "13.284"], ["2288.58", "0.727"], ["2288.68", "3.529"], ["2288.77", "10.882"], ["2288.91", "2.790"], ["2288.99", "48.988"], ["2289.02", "27.945"], ["2289.04", "159.235"], ["2289.12", "12.233"], ["2289.14", "1.090"], ["2289.19", "3.211"], ["2289.29", "0.600"], ["2289.37", "2.348"], ["2289.45", "0.496"], ["2289.57", "5.044"], ["2289.60", "24.119"], ["2289.72", "0.350"], ["2289.83", "1.561"], ["2289.94", "0.057"], ["2290.04", "19.363"], ["2290.06", "66.156"], ["2290.29", "0.000"], ["2290.91", "0.082"], ["2291.98", "11.159"], ["2293.86", "0.104"]]}
{"e": "depthUpdate", "E": 1703936452777, "T": 1703936452772, "s": "ETHUSDT", "U": 3743827086031, "u": 3743827089083, "pu": 3743827085903, "b": [["500.00", "184.422"], ["1000.00", "127.045"], ["2173.03", "0.917"], ["2264.53", "15.142"], ["2266.85", "0.590"], ["2278.83", "0.000"], ["2280.71", "45.878"], ["2284.39", "7.809"], ["2285.95", "0.000"], ["2286.27", "9.258"]], "a": [["2287.41", "6.651"], ["2287.62", "1.410"], ["2287.75", "0.412"], ["2287.91", "0.804"], ["2288.07", "19.183"], ["2288.09", "5.175"], ["2288.21", "7.357"], ["2288.30", "3.591"], ["2288.31", "1.747"], ["2288.44", "26.269"], ["2288.53", "2.919"], ["2288.54", "5.100"], ["2288.67", "1.527"], ["2288.76", "25.815"], ["2288.77", "10.682"], ["2288.90", "11.394"], ["2288.99", "49.188"], ["2289.00", "8.524"], ["2289.13", "1.020"], ["2289.22", "15.796"], ["2289.23", "2.676"], ["2289.35", "3.820"], ["2289.44", "10.518"], ["2289.45", "0.696"], ["2289.46", "6.626"], ["2289.58", "0.210"], ["2289.68", "0.815"], ["2289.69", "0.020"], ["2289.81", "0.905"], ["2289.91", "2.896"], ["2289.92", "23.803"], ["2290.04", "19.563"], ["2290.13", "0.862"], ["2290.15", "12.613"], ["2290.27", "0.374"], ["2291.33", "8.101"], ["2295.66", "2.748"], ["2297.55", "0.267"]]}
{"e": "depthUpdate", "E": 1703936452880, "T": 1703936452870, "s": "ETHUSDT", "U": 3743827089194, "u": 3743827091285, "pu": 3743827089083, "b": [["500.00", "184.422"], ["1000.00", "127.045"], ["2012.92", "0.187"], ["2195.91", "0.054"], ["2263.85", "2.117"], ["2283.41", "13.016"], ["2283.45", "0.000"], ["2283.47", "12.208"], ["2285.95", "0.000"]], "a": [["2288.10", "17.235"], ["2460.85", "0.020"]]}
{"e": "depthUpdate", "E": 1703936452985, "T": 1703936452985, "s": "ETHUSDT", "U": 3743827092165, "u": 3743827098568, "pu": 3743827091285, "b": [["500.00", "184.422"], ["1000.00", "127.045"], ["2242.34", "53.448"], ["2264.53", "15.142"], ["2266.67", "0.654"], ["2283.41", "23.016"], ["2283.45", "36.000"], ["2283.47", "48.208"], ["2284.77", "0.222"], ["2284.78", "0.200"], ["2284.83", "19.490"], ["2285.00", "53.684"], ["2285.01", "45.329"], ["2285.05", "1.000"], ["2285.06", "38.393"], ["2285.11", "0.018"], ["2285.23", "11.901"], ["2285.24", "6.177"], ["2285.28", "13.731"], ["2285.29", "35.810"], ["2285.46", "0.265"], ["2285.47", "7.315"], ["2285.51", "11.641"], ["2285.52", "0.415"], ["2285.69", "1.796"], ["2285.74", "44.515"], ["2285.75", "0.805"], ["2285.92", "17.106"], ["2285.95", "0.000"], ["2285.97", "4.013"], ["2286.14", "5.628"], ["2286.15", "12.663"], ["2286.20", "15.321"], ["2286.37", "1.223"], ["2286.38", "0.424"], ["2286.43", "33.840"], ["2286.60", "6.124"], ["2286.61", "9.168"], ["2286.65", "20.879"], ["2286.66", "30.275"], ["2286.81", "32.324"], ["2286.83", "1.394"], ["2286.84", "16.017"], ["2286.88", "22.804"], ["2286.89", "8.069"], ["2287.01", "23.873"], ["2287.39", "21.597"]], "a": [["2287.41", "16.285"], ["2287.62", "2.678"], ["2287.66", "9.406"], ["2287.67", "8.604"], ["2287.75", "0.363"], ["2287.76", "7.848"], ["2287.77", "4.630"], ["2289.70", "5.809"], ["2292.28", "0.076"], ["2292.30", "12.370"], ["2300.66", "761.374"], ["2301.30", "0.065"], ["2346.68", "8.829"], ["2401.76", "0.053"]]}
{"e": "depthUpdate", "E": 1703936453087, "T": 1703936453086, "s": "ETHUSDT", "U": 3743827098575, "u": 3743827102311, "pu": 3743827098568, "b": [["500.00", "184.422"], ["1000.00", "127.045"], ["1143.70", "0.043"], ["2264.53", "19.043"], ["2266.85", "0.599"], ["2278.67", "0.472"], ["2280.55", "0.010"], ["2283.76", "0.015"], ["2284.05", "8.457"], ["2284.39", "0.053"], ["2285.19", "9.066"], ["2285.27", "6.208"], ["2285.28", "13.331"], ["2285.30", "25.965"], ["2285.31", "47.234"], ["2285.82", "5.808"], ["2285.93", "14.302"], ["2285.94", "1.929"], ["2285.95", "0.000"], ["2286.27", "2.207"], ["2286.55", "2.514"], ["2286.58", "1.374"], ["2286.65", "19.786"], ["2286.68", "2.687"], ["2286.71", "33.542"], ["2286.72", "8.786"], ["2286.73", "0.792"], ["2286.81", "32.589"], ["2286.83", "1.129"], ["2287.01", "10.767"], ["2287.02", "19.257"], ["2287.05", "1.523"], ["2287.09", "0.000"]], "a": [["2287.41", "16.185"], ["2287.60", "4.211"], ["2287.63", "6.000"], ["2287.64", "2.630"], ["2287.65", "5.465"], ["2287.69", "0.280"], ["2287.73", "12.677"], ["2287.75", "0.366"], ["2287.77", "2.630"], ["2287.93", "0.922"], ["2288.05", "5.304"], ["2288.14", "23.253"], ["2288.15", "23.636"], ["2288.17", "3.746"], ["2288.24", "21.175"], ["2288.29", "22.637"], ["2288.38", "11.361"], ["2288.39", "24.659"], ["2288.61", "0.800"], ["2288.62", "2.411"], ["2288.75", "1.052"], ["2288.76", "26.215"], ["2288.77", "10.182"], ["2288.78", "0.000"], ["2288.84", "22.602"], ["2288.85", "1.246"], ["2289.03", "164.513"], ["2289.04", "0.121"], ["2289.07", "3.807"], ["2289.08", "0.824"], ["2289.30", "5.714"], ["2289.31", "27.164"], ["2289.44", "10.422"], ["2289.52", "13.588"], ["2289.54", "1.842"], ["2289.75", "1.053"], ["2289.77", "4.132"], ["2289.98", "1.012"], ["2290.00", "20.123"], ["2290.10", "36.728"], ["2290.21", "1.000"], ["2290.23", "5.669"], ["2290.79", "5.066"], ["2291.33", "7.995"], ["2292.28", "10.076"], ["2292.30", "84.370"], ["2295.68", "0.769"], ["2297.57", "0.365"], ["2310.28", "4.432"], ["3130.12", "0.002"]]}
{"e": "depthUpdate", "E": 1703936453188, "T": 1703936453182, "s": "ETHUSDT", "U": 3743827102321, "u": 3743827105842, "pu": 3743827102311, "b": [["500.00", "184.422"], ["1000.00", "127.045"], ["1143.70", "0.000"], ["2257.82", "116.814"], ["2264.53", "15.142"], ["2285.95", "0.000"], ["2286.64", "1.527"], ["2286.66", "31.149"], ["2287.39", "21.755"], ["2287.40", "144.400"]], "a": [["2287.66", "0.790"], ["2287.67", "0.295"], ["2287.75", "2.522"], ["2287.91", "0.804"], ["2287.98", "1.971"], ["2288.24", "21.001"], ["2288.26", "8.466"], ["2288.39", "24.759"], ["2288.41", "69.443"], ["2288.46", "25.490"], ["2288.69", "0.960"], ["2288.72", "1.203"], ["2288.84", "21.510"], ["2288.87", "4.385"], ["2289.35", "0.820"], ["2310.28", "4.432"], ["2346.20", "9.308"], ["2375.46", "0.220"], ["2401.76", "0.010"]]}
{"e": "depthUpdate", "E": 1703936453289, "T": 1703936453288, "s": "ETHUSDT", "U": 3743827106849, "u": 3743827120672, "pu": 3743827105842, "b": [["500.00", "184.422"], ["1000.00", "127.045"], ["2058.66", "0.616"], ["2173.03", "0.960"], ["2241.65", "71.342"], ["2264.53", "15.142"], ["2264.54", "1.076"], ["2266.67", "2.373"], ["2275.97", "0.051"], ["2276.02", "1.176"], ["2284.83", "19.490"], ["2285.06", "38.393"], ["2285.29", "35.810"], ["2285.51", "11.441"], ["2285.52", "0.615"], ["2285.74", "44.315"], ["2285.75", "1.005"], ["2285.95", "0.282"], ["2285.97", "3.813"], ["2285.98", "1.383"], ["2286.02", "0.000"], ["2286.20", "15.121"], ["2286.21", "15.400"], ["2286.34", "0.826"], ["2286.43", "33.840"], ["2286.48", "15.964"], ["2286.62", "23.037"], ["2286.65", "19.574"], ["2286.66", "31.149"], ["2286.67", "25.196"], ["2286.77", "10.240"], ["2286.78", "2.148"], ["2286.81", "32.324"], ["2286.83", "1.303"], ["2286.84", "1.876"], ["2286.85", "5.872"], ["2286.89", "8.069"], ["2287.01", "7.286"], ["2287.02", "7.021"], ["2287.03", "9.519"], ["2287.04", "4.215"], ["2287.05", "0.439"], ["2287.17", "5.288"], ["2287.19", "0.153"], ["2287.22", "6.654"], ["2287.24", "0.191"], ["2287.40", "151.048"]], "a": [["2287.41", "6.785"], ["2287.53", "0.000"], ["2287.54", "1.246"], ["2287.58", "0.000"], ["2287.60", "0.009"], ["2287.62", "1.111"], ["2287.63", "3.493"], ["2287.64", "2.630"], ["2287.65", "0.000"], ["2287.67", "3.788"], ["2287.70", "11.445"], ["2287.72", "25.382"], ["2287.75", "0.260"], ["2287.76", "7.848"], ["2287.82", "6.273"], ["2287.83", "17.938"], ["2287.89", "10.412"], ["2287.92", "0.095"], ["2287.95", "3.813"], ["2287.98", "1.958"], ["2288.00", "4.291"], ["2288.01", "3.950"], ["2288.02", "33.644"], ["2288.03", "1.311"], ["2288.10", "6.000"], ["2288.13", "2.765"], ["2288.14", "1.402"], ["2288.15", "23.436"], ["2288.17", "3.746"], ["2288.19", "22.103"], ["2288.21", "7.357"], ["2288.26", "8.292"], ["2288.29", "18.844"], ["2288.32", "17.495"], ["2288.34", "24.689"], ["2288.35", "55.962"], ["2288.36", "11.224"], ["2288.37", "1.120"], ["2288.38", "11.161"], ["2288.39", "24.659"], ["2288.43", "11.572"], ["2288.44", "0.234"], ["2288.56", "5.025"], ["2288.59", "18.346"], ["2288.61", "0.600"], ["2288.64", "30.640"], ["2288.82", "0.200"], ["2288.83", "31.631"], ["2288.84", "0.615"], ["2288.99", "8.925"], ["2289.03", "4.231"], ["2289.05", "2.579"], ["2289.06", "0.400"], ["2289.09", "4.509"], ["2289.12", "12.233"], ["2289.14", "161.372"], ["2289.28", "1.271"], ["2289.29", "0.400"], ["2289.51", "0.600"], ["2289.52", "13.388"], ["2289.74", "20.431"], ["2289.75", "0.853"], ["2289.88", "13.522"], ["2289.97", "0.600"], ["2289.98", "0.812"], ["2290.19", "0.287"], ["2290.21", "0.800"], ["2292.59", "92.225"], ["2296.59", "0.788"], ["2298.84", "0.000"], ["2298.90", "1.519"], ["2310.27", "0.085"], ["2310.28", "4.432"], ["2376.19", "0.011"]]}
{"e": "depthUpdate", "E": 1703936453394, "T": 1703936453394, "s": "ETHUSDT", "U": 3743827121080, "u": 3743827126592, "pu": 3743827120672, "b": [["500.00", "184.422"], ["2173.03", "0.917"], ["2257.66", "43.823"], ["2264.53", "15.142"], ["2264.54", "1.076"], ["2276.02", "0.141"], ["2284.83", "19.490"], ["2285.05", "0.800"], ["2285.06", "38.593"], ["2285.27", "6.608"], ["2285.28", "13.531"], ["2285.29", "36.010"], ["2285.30", "25.565"], ["2285.31", "46.834"], ["2285.51", "11.241"], ["2285.52", "0.815"], ["2285.74", "44.115"], ["2285.75", "1.205"], ["2285.95", "0.000"], ["2285.97", "3.813"], ["2286.20", "15.121"], ["2286.26", "6.220"], ["2286.43", "33.840"], ["2286.65", "19.374"], ["2286.66", "31.349"], ["2286.67", "18.638"], ["2286.70", "19.179"], ["2286.83", "1.394"], ["2286.88", "22.604"], ["2286.89", "8.269"], ["2287.02", "3.742"], ["2287.04", "4.215"], ["2287.39", "21.913"], ["2287.40", "151.024"]], "a": [["2287.63", "0.000"], ["2287.75", "0.018"], ["2288.06", "24.022"], ["2288.21", "10.357"], ["2288.29", "19.044"], ["2288.31", "5.926"], ["2288.34", "31.734"], ["2288.35", "55.962"], ["2288.45", "19.430"], ["2288.49", "18.781"], ["2288.52", "3.068"], ["2288.75", "0.852"], ["2288.76", "25.815"], ["2288.77", "10.182"], ["2288.78", "0.000"], ["2288.79", "1.946"], ["2288.80", "6.239"], ["2288.87", "25.279"], ["2288.98", "1.456"], ["2289.12", "172.515"], ["2289.14", "1.090"], ["2289.21", "9.734"], ["2289.44", "10.622"], ["2289.67", "5.173"], ["2289.70", "8.809"], ["2289.89", "1.931"], ["2290.12", "1.670"], ["2291.72", "10.677"], ["2300.67", "0.000"], ["2310.28", "4.432"], ["2378.90", "56.016"]]}
{"e": "depthUpdate", "E": 1703936453504, "T": 1703936453503, "s": "ETHUSDT", "U": 3743827127030, "u": 3743827131427, "pu": 3743827126592, "b": [["500.00", "184.462"], ["1000.00", "127.045"], ["2227.52", "0.178"], ["2264.53", "15.142"], ["2264.54", "0.041"], ["2266.85", "0.590"], ["2276.02", "1.176"], ["2283.41", "13.016"], ["2283.45", "0.000"], ["2283.47", "12.208"], ["2285.95", "0.282"], ["2287.19", "6.798"], ["2287.22", "0.009"], ["2287.29", "2.979"]], "a": [["2287.75", "0.167"], ["2288.07", "18.983"], ["2288.30", "3.391"], ["2288.53", "2.719"], ["2288.76", "25.615"], ["2288.79", "2.046"], ["2288.99", "8.725"], ["2289.08", "0.824"], ["2289.09", "4.509"], ["2289.11", "163.791"], ["2289.12", "12.233"], ["2289.22", "15.596"], ["2289.45", "0.496"], ["2289.68", "0.615"], ["2289.91", "2.696"], ["2290.07", "11.988"], ["2290.13", "0.662"], ["2291.02", "38.201"], ["2291.76", "36.596"], ["2292.28", "0.076"], ["2292.30", "12.370"], ["2295.38", "14.048"], ["2310.28", "4.432"], ["2322.42", "0.168"]]}
{"e": "depthUpdate", "E": 1703936453606, "T": 1703936453604, "s": "ETHUSDT", "U": 3743827131519, "u": 3743827136219, "pu": 3743827131427, "b": [["500.00", "184.422"], ["1000.00", "127.045"], ["1143.70", "0.043"], ["2264.53", "19.975"], ["2266.68", "1.472"], ["2283.41", "23.016"], ["2283.45", "36.000"], ["2283.47", "48.208"], ["2284.82", "1.028"], ["2284.83", "19.690"], ["2284.85", "0.991"], ["2284.86", "1.009"], ["2285.05", "0.600"], ["2285.06", "38.793"], ["2285.08", "14.874"], ["2285.28", "13.531"], ["2285.31", "46.834"], ["2285.51", "11.241"], ["2285.54", "27.076"], ["2285.74", "44.115"], ["2285.77", "31.730"], ["2285.95", "0.282"], ["2285.96", "2.219"], ["2285.97", "4.013"], ["2285.99", "10.516"], ["2286.00", "44.579"], ["2286.19", "0.800"], ["2286.20", "15.321"], ["2286.22", "3.604"], ["2286.23", "8.744"], ["2286.42", "0.800"], ["2286.43", "34.040"], ["2286.45", "51.477"], ["2286.46", "43.929"], ["2286.58", "2.686"], ["2286.65", "19.174"], ["2286.66", "31.549"], ["2286.68", "2.687"], ["2286.71", "11.677"], ["2286.72", "7.474"], ["2286.73", "22.657"], ["2286.83", "2.050"], ["2286.88", "22.604"], ["2286.91", "9.648"], ["2286.93", "2.647"], ["2287.04", "1.318"], ["2287.13", "18.411"], ["2287.40", "151.859"]], "a": [["2287.41", "6.385"], ["2287.72", "4.396"], ["2287.75", "0.220"], ["2287.76", "28.834"], ["2287.91", "0.804"], ["2287.97", "0.000"], ["2288.15", "45.287"], ["2288.17", "3.746"], ["2288.19", "0.252"], ["2288.21", "10.377"], ["2288.22", "26.285"], ["2288.30", "25.050"], ["2288.31", "1.747"], ["2288.32", "0.015"], ["2288.34", "31.734"], ["2289.09", "164.989"], ["2289.11", "3.311"], ["2292.30", "22.370"], ["2292.31", "72.614"], ["2299.06", "19.601"], ["2310.28", "9.265"], ["2401.76", "0.053"]]}
{"e": "depthUpdate", "E": 1703936453707, "T": 1703936453705, "s": "ETHUSDT", "U": 3743827136258, "u": 3743827143829, "pu": 3743827136219, "b": [["500.00", "184.422"], ["1000.00", "127.045"], ["1143.70", "0.000"], ["2227.93", "28.504"], ["2264.53", "21.997"], ["2285.95", "0.000"], ["2286.48", "16.006"], ["2287.33", "1.749"]], "a": [["2287.75", "0.018"], ["2287.90", "17.433"], ["2288.06", "24.130"], ["2288.07", "19.183"], ["2288.15", "45.287"], ["2288.17", "3.746"], ["2288.21", "10.357"], ["2288.25", "21.763"], ["2288.29", "19.244"], ["2288.30", "7.570"], ["2288.32", "17.495"], ["2288.44", "7.652"], ["2288.52", "3.268"], ["2288.59", "19.096"], ["2288.75", "1.052"], ["2288.79", "1.296"], ["2288.98", "1.656"], ["2289.08", "161.304"], ["2289.09", "4.509"], ["2289.11", "6.873"], ["2289.21", "9.934"], ["2289.44", "10.822"], ["2289.67", "5.373"], ["2289.90", "4.461"], ["2290.13", "0.862"], ["2293.94", "0.100"], ["2293.95", "0.000"], ["2310.28", "2.410"], ["2346.68", "0.316"], ["2401.76", "0.010"]]}
{"e": "depthUpdate", "E": 1703936453809, "T": 1703936453807, "s": "ETHUSDT", "U": 3743827143973, "u": 3743827149241, "pu": 3743827143829, "b": [["500.00", "184.422"], ["1000.00", "127.045"], ["2012.92", "0.187"], ["2173.03", "0.960"], ["2264.53", "21.997"], ["2285.95", "0.000"], ["2286.48", "15.964"], ["2287.39", "21.901"], ["2287.40", "145.382"]], "a": [["2287.75", "0.159"], ["2288.08", "3.685"], ["2288.15", "23.636"], ["2288.17", "25.397"], ["2288.31", "1.547"], ["2288.38", "11.361"], ["2288.40", "4.217"], ["2288.53", "2.519"], ["2288.61", "0.800"], ["2288.62", "2.211"], ["2288.76", "25.415"], ["2288.79", "1.196"], ["2288.82", "0.300"], ["2288.84", "0.815"], ["2288.85", "1.046"], ["2288.99", "8.525"], ["2289.07", "4.007"], ["2289.08", "0.624"], ["2289.11", "167.353"], ["2289.22", "15.396"], ["2289.30", "5.914"], ["2289.31", "26.964"], ["2289.45", "0.296"], ["2289.53", "45.703"], ["2289.54", "1.642"], ["2289.68", "0.415"], ["2289.75", "1.053"], ["2289.77", "3.932"], ["2289.91", "2.496"], ["2289.98", "1.012"], ["2290.00", "19.923"], ["2290.14", "0.200"], ["2290.21", "1.000"], ["2290.23", "5.469"], ["2310.28", "2.410"]]}
{"e": "depthUpdate", "E": 1703936453910, "T": 1703936453910, "s": "ETHUSDT", "U": 3743827149303, "u": 3743827157647, "pu": 3743827149241, "b": [["500.00", "184.422"], ["1000.00", "127.045"], ["2173.03", "0.917"], ["2195.91", "0.054"], ["2241.55", "0.122"], ["2252.88", "1.020"], ["2264.19", "0.151"], ["2264.20", "0.142"], ["2264.53", "18.096"], ["2264.54", "0.041"], ["2266.85", "0.599"], ["2275.99", "1.078"], ["2276.02", "0.141"], ["2283.10", "0.288"], ["2283.20", "0.953"], ["2283.24", "0.657"], ["2283.40", "100.274"], ["2284.55", "0.040"], ["2284.84", "0.647"], ["2285.42", "62.197"], ["2285.95", "0.000"], ["2286.28", "0.284"], ["2286.29", "2.318"], ["2286.35", "72.503"], ["2286.47", "14.559"], ["2286.48", "2.521"], ["2286.58", "2.487"], ["2286.62", "9.552"], ["2286.68", "16.172"], ["2286.70", "25.832"], ["2286.77", "4.094"], ["2286.80", "7.366"], ["2286.82", "10.755"], ["2286.83", "15.535"], ["2286.91", "5.469"], ["2286.94", "4.467"], ["2286.98", "2.505"], ["2287.03", "6.038"], ["2287.05", "3.718"], ["2287.06", "4.161"], ["2287.32", "0.000"], ["2287.33", "0.000"], ["2287.39", "12.035"], ["2287.40", "31.111"], ["2287.41", "22.987"], ["2287.42", "142.471"], ["2287.55", "0.000"]], "a": [["2287.41", "0.000"], ["2287.42", "0.000"], ["2287.43", "8.765"], ["2287.56", "5.171"], ["2287.62", "2.607"], ["2287.63", "3.493"], ["2287.65", "4.658"], ["2287.66", "0.790"], ["2287.67", "0.024"], ["2287.68", "7.405"], ["2287.75", "0.160"], ["2287.82", "6.178"], ["2287.90", "5.757"], ["2287.91", "0.784"], ["2287.93", "20.234"], ["2288.01", "15.721"], ["2288.05", "0.646"], ["2288.17", "0.195"], ["2288.19", "22.207"], ["2288.22", "14.514"], ["2288.25", "21.913"], ["2288.30", "3.391"], ["2288.33", "0.225"], ["2288.41", "5.496"], ["2288.45", "1.513"], ["2288.47", "81.437"], ["2288.49", "18.885"], ["2288.52", "1.068"], ["2288.53", "0.819"], ["2288.63", "4.510"], ["2288.68", "2.229"], ["2288.80", "4.939"], ["2288.81", "0.619"], ["2288.87", "4.385"], ["2289.02", "23.574"], ["2289.43", "79.661"], ["2289.50", "0.420"], ["2289.83", "0.666"], ["2290.00", "19.468"], ["2291.49", "0.594"], ["2291.79", "0.000"], ["2292.26", "184.501"], ["2292.27", "41.000"], ["2297.75", "0.052"], ["2297.76", "41.895"], ["2310.28", "0.531"], ["2312.42", "8.811"], ["2312.44", "0.040"], ["2323.76", "0.141"], ["2335.09", "0.335"], ["2346.20", "17.823"]]}
{"e": "depthUpdate", "E": 1703936454012, "T": 1703936454011, "s": "ETHUSDT", "U": 3743827157776, "u": 3743827164258, "pu": 3743827157647, "b": [["500.00", "184.422"], ["2173.05", "0.000"], ["2264.53", "15.142"], ["2264.55", "3.983"], ["2266.85", "0.590"], ["2277.16", "0.062"], ["2277.22", "42.000"], ["2278.01", "0.880"], ["2280.28", "0.273"], ["2282.55", "1.682"], ["2285.13", "0.706"], ["2285.95", "0.282"], ["2286.32", "4.146"], ["2286.70", "19.274"], ["2286.73", "0.792"], ["2286.77", "25.958"], ["2286.83", "15.270"], ["2286.86", "1.059"], ["2286.88", "22.869"], ["2287.03", "1.609"], ["2287.05", "2.919"], ["2287.07", "0.042"], ["2287.13", "17.327"], ["2287.21", "2.086"], ["2287.24", "0.201"], ["2287.29", "2.189"], ["2287.34", "0.790"], ["2287.39", "12.026"], ["2287.40", "29.363"], ["2287.41", "22.996"], ["2287.42", "154.742"]], "a": [["2287.43", "9.576"], ["2287.44", "0.009"], ["2287.54", "2.462"], ["2287.62", "0.000"], ["2287.63", "0.000"], ["2287.65", "0.000"], ["2287.66", "0.000"], ["2287.68", "0.000"], ["2287.69", "0.271"], ["2287.71", "13.445"], ["2287.72", "13.771"], ["2287.75", "6.888"], ["2287.76", "28.476"], ["2287.77", "2.630"], ["2287.78", "10.670"], ["2287.81", "1.116"], ["2287.82", "0.132"], ["2287.85", "12.606"], ["2288.00", "5.603"], ["2288.01", "14.409"], ["2288.06", "24.022"], ["2288.10", "6.223"], ["2288.12", "22.381"], ["2288.17", "3.570"], ["2288.19", "0.356"], ["2288.21", "43.979"], ["2288.27", "7.891"], ["2288.29", "19.070"], ["2288.31", "5.726"], ["2288.32", "0.015"], ["2288.34", "31.908"], ["2288.38", "28.840"], ["2288.40", "15.988"], ["2288.45", "7.659"], ["2288.64", "26.232"], ["2288.73", "0.009"], ["2288.82", "0.200"], ["2288.83", "52.526"], ["2288.86", "3.589"], ["2289.09", "4.609"], ["2289.11", "6.873"], ["2289.14", "1.090"], ["2289.21", "13.427"], ["2289.23", "167.093"], ["2289.24", "0.724"], ["2289.38", "5.594"], ["2289.42", "9.277"], ["2289.70", "9.184"], ["2289.72", "0.350"], ["2289.88", "18.736"], ["2290.16", "0.486"], ["2292.07", "0.060"], ["2292.63", "0.009"], ["2292.69", "18.616"], ["2294.34", "0.060"], ["2296.59", "0.730"], ["2297.78", "0.026"], ["2298.90", "0.554"], ["2310.27", "1.050"], ["2310.28", "0.531"], ["2310.30", "2.810"], ["2333.87", "53.536"], ["2460.09", "0.030"]]}
{"e": "depthUpdate", "E": 1703936454113, "T": 1703936454113, "s": "ETHUSDT", "U": 3743827164267, "u": 3743827170338, "pu": 3743827164258, "b": [["500.00", "184.422"], ["1000.00", "127.045"], ["2173.05", "0.043"], ["2264.55", "3.036"], ["2266.85", "0.599"], ["2278.01", "0.938"], ["2280.28", "0.331"], ["2282.53", "0.058"], ["2283.41", "23.016"], ["2283.45", "36.000"], ["2283.47", "48.208"], ["2283.57", "0.020"], ["2283.98", "4.147"], ["2284.82", "0.828"], ["2284.85", "0.991"], ["2284.88", "5.494"], ["2285.05", "0.400"], ["2285.08", "14.874"], ["2285.11", "0.218"], ["2285.28", "13.331"], ["2285.31", "46.834"], ["2285.33", "15.755"], ["2285.51", "11.041"], ["2285.53", "0.610"], ["2285.54", "26.876"], ["2285.56", "0.215"], ["2285.74", "43.915"], ["2285.76", "9.411"], ["2285.77", "31.530"], ["2285.79", "1.553"], ["2285.95", "0.000"], ["2285.96", "2.301"], ["2285.99", "10.716"], ["2286.00", "44.379"], ["2286.02", "0.200"], ["2286.03", "2.967"], ["2286.16", "31.675"], ["2286.18", "0.029"], ["2286.19", "0.600"], ["2286.22", "3.604"], ["2286.25", "0.385"], ["2286.38", "0.519"], ["2286.39", "15.002"], ["2286.42", "0.600"], ["2286.44", "19.188"], ["2286.45", "51.477"], ["2286.48", "2.679"], ["2286.54", "36.077"], ["2286.61", "9.168"], ["2286.65", "18.974"], ["2286.66", "30.675"], ["2286.68", "15.079"], ["2286.70", "19.179"], ["2286.71", "11.877"], ["2286.73", "1.666"], ["2286.74", "1.093"], ["2286.80", "1.220"], ["2286.84", "2.141"], ["2286.86", "1.059"], ["2286.88", "22.404"], ["2286.91", "5.469"], ["2286.94", "0.488"], ["2287.05", "4.868"], ["2287.21", "1.002"], ["2287.39", "11.933"], ["2287.40", "24.974"], ["2287.41", "16.116"], ["2287.42", "147.468"]], "a": [["2287.42", "0.000"], ["2287.43", "5.718"], ["2287.61", "2.186"], ["2287.65", "5.465"], ["2287.68", "25.684"], ["2287.69", "12.354"], ["2287.70", "17.445"], ["2287.71", "7.445"], ["2287.72", "7.028"], ["2287.75", "0.018"], ["2287.76", "7.848"], ["2287.77", "2.749"], ["2287.78", "10.670"], ["2287.79", "0.224"], ["2287.80", "31.624"], ["2287.82", "21.118"], ["2287.83", "24.592"], ["2287.85", "0.264"], ["2287.86", "0.095"], ["2287.87", "0.000"], ["2287.89", "17.306"], ["2287.90", "5.662"], ["2287.92", "0.000"], ["2287.96", "8.830"], ["2287.98", "1.863"], ["2288.16", "5.311"], ["2288.17", "3.770"], ["2288.25", "26.092"], ["2288.27", "7.891"], ["2288.30", "9.949"], ["2288.31", "1.547"], ["2288.32", "0.189"], ["2288.34", "31.734"], ["2288.39", "30.805"], ["2288.40", "16.188"], ["2288.41", "5.496"], ["2288.45", "1.513"], ["2288.63", "4.710"], ["2288.64", "30.640"], ["2288.66", "2.413"], ["2288.72", "0.330"], ["2288.78", "0.873"], ["2288.86", "3.789"], ["2288.87", "3.293"], ["2288.94", "2.917"], ["2289.09", "4.709"], ["2289.20", "168.416"], ["2289.23", "2.676"], ["2289.31", "27.164"], ["2289.54", "1.842"], ["2289.57", "8.323"], ["2289.77", "4.132"], ["2290.00", "19.668"], ["2290.23", "5.669"], ["2290.49", "6.738"], ["2291.92", "3.338"], ["2292.30", "12.370"], ["2292.31", "10.614"], ["2292.32", "73.877"], ["2294.19", "2.776"], ["2296.44", "0.548"], ["2297.84", "42.159"], ["2298.92", "1.037"], ["2310.27", "0.085"], ["2310.30", "6.711"]]}
{"e": "depthUpdate", "E": 1703936454216, "T": 1703936454214, "s": "ETHUSDT", "U": 3743827170388, "u": 3743827174829, "pu": 3743827170338, "b": [["500.00", "184.422"], ["1000.00", "127.045"], ["2058.68", "0.111"], ["2173.05", "0.000"], ["2264.55", "6.958"], ["2266.85", "0.590"], ["2285.96", "2.301"], ["2285.97", "4.013"], ["2286.00", "44.379"], ["2286.03", "7.181"], ["2286.17", "13.657"], ["2286.41", "26.205"], ["2286.50", "0.517"], ["2286.60", "4.524"], ["2286.79", "25.458"], ["2286.86", "1.459"], ["2286.87", "21.466"], ["2286.88", "18.742"], ["2286.89", "6.083"], ["2286.90", "0.230"], ["2286.91", "5.032"], ["2286.92", "1.693"], ["2286.93", "6.826"], ["2286.95", "2.324"], ["2286.96", "10.601"], ["2286.97", "20.721"], ["2286.99", "5.956"], ["2287.00", "3.606"], ["2287.05", "5.305"], ["2287.40", "23.309"], ["2287.41", "0.816"], ["2287.42", "149.181"]], "a": [["2287.60", "0.009"], ["2287.62", "7.509"], ["2287.63", "8.651"], ["2287.64", "10.980"], ["2287.67", "8.668"], ["2287.68", "1.331"], ["2287.69", "8.861"], ["2287.73", "12.804"], ["2287.77", "2.850"], ["2287.84", "0.623"], ["2287.88", "0.000"], ["2287.90", "5.642"], ["2287.93", "20.234"], ["2288.06", "24.042"], ["2288.10", "6.000"], ["2288.16", "5.111"], ["2288.25", "21.913"], ["2288.26", "8.466"], ["2288.29", "23.249"], ["2288.32", "0.015"], ["2288.39", "24.459"], ["2288.43", "17.718"], ["2288.62", "2.011"], ["2288.85", "0.846"], ["2289.08", "0.424"], ["2289.14", "162.014"], ["2289.15", "1.456"], ["2289.19", "3.211"], ["2289.20", "7.492"], ["2289.31", "26.964"], ["2289.54", "1.642"], ["2289.60", "24.271"], ["2289.77", "3.932"], ["2290.00", "19.468"], ["2290.22", "2.608"], ["2290.47", "2.728"], ["2290.71", "0.380"], ["2300.05", "0.352"], ["2310.30", "10.633"], ["2360.96", "1.439"], ["2593.90", "0.089"]]}
{"e": "depthUpdate", "E": 1703936454318, "T": 1703936454318, "s": "ETHUSDT", "U": 3743827174934, "u": 3743827179777, "pu": 3743827174829, "b": [["500.00", "184.422"], ["1000.00", "127.045"], ["2058.68", "0.099"], ["2173.05", "0.043"], ["2264.55", "3.036"], ["2266.85", "0.599"], ["2285.96", "2.019"], ["2286.29", "66.244"], ["2286.35", "8.556"], ["2286.57", "34.452"], ["2286.73", "23.531"], ["2286.77", "4.094"], ["2287.39", "10.626"], ["2287.42", "145.172"]], "a": [["2287.43", "11.806"], ["2287.60", "8.616"], ["2287.62", "3.200"], ["2287.63", "0.000"], ["2287.64", "2.630"], ["2287.68", "15.042"], ["2287.72", "0.790"], ["2287.77", "2.715"], ["2287.89", "17.326"], ["2288.06", "24.022"], ["2288.15", "45.487"], ["2288.16", "4.911"], ["2288.17", "3.970"], ["2288.21", "22.128"], ["2288.26", "8.292"], ["2288.29", "23.423"], ["2288.39", "24.259"], ["2288.40", "16.388"], ["2288.41", "5.474"], ["2288.62", "2.011"], ["2288.85", "0.846"], ["2289.05", "163.503"], ["2289.06", "0.400"], ["2289.08", "0.424"], ["2289.14", "1.090"], ["2289.19", "3.311"], ["2289.31", "26.964"], ["2289.53", "45.503"], ["2289.54", "1.842"], ["2289.76", "0.224"], ["2289.77", "4.132"], ["2289.99", "0.209"], ["2290.00", "19.668"], ["2290.22", "2.408"], ["2290.23", "5.869"], ["2298.92", "0.072"], ["2310.29", "3.175"], ["2310.30", "6.711"], ["2333.18", "11.190"]]}
{"e": "depthUpdate", "E": 1703936454421, "T": 1703936454420, "s": "ETHUSDT", "U": 3743827179839, "u": 3743827183931, "pu": 3743827179777, "b": [["500.00", "184.422"], ["1000.00", "127.045"], ["2173.05", "0.000"], ["2264.55", "3.983"], ["2284.83", "19.490"], ["2284.85", "1.191"], ["2285.06", "38.593"], ["2285.08", "15.074"], ["2285.28", "13.131"], ["2285.31", "47.034"], ["2285.51", "10.841"], ["2285.54", "27.076"], ["2285.74", "43.715"], ["2285.77", "31.730"], ["2285.96", "2.301"], ["2285.97", "3.813"], ["2286.00", "44.579"], ["2286.20", "15.121"], ["2286.22", "3.804"], ["2286.43", "33.840"], ["2286.45", "51.677"], ["2286.50", "0.475"], ["2286.58", "1.175"], ["2286.59", "1.214"], ["2286.64", "0.215"], ["2286.66", "30.475"], ["2286.68", "15.279"], ["2286.71", "33.742"], ["2286.72", "10.098"], ["2286.73", "1.666"], ["2286.82", "11.020"], ["2286.83", "15.670"], ["2286.84", "1.876"], ["2286.86", "1.059"], ["2286.88", "18.542"], ["2286.91", "5.232"], ["2286.92", "1.703"], ["2287.11", "29.816"], ["2287.17", "11.933"], ["2287.19", "0.153"], ["2287.24", "0.191"], ["2287.40", "22.213"], ["2287.42", "142.788"]], "a": [["2287.43", "16.806"], ["2287.77", "2.859"], ["2288.26", "8.466"], ["2288.28", "12.035"], ["2288.29", "23.249"], ["2288.56", "5.015"], ["2289.04", "161.045"], ["2289.05", "2.579"], ["2289.19", "3.211"], ["2298.91", "1.901"], ["2310.29", "2.210"], ["2310.30", "5.764"], ["2378.92", "0.000"], ["2401.79", "0.065"]]}
{"e": "depthUpdate", "E": 1703936454523, "T": 1703936454520, "s": "ETHUSDT", "U": 3743827183945, "u": 3743827187474, "pu": 3743827183931, "b": [["500.00", "184.422"], ["2125.00", "698.101"], ["2251.41", "0.140"], ["2264.55", "7.905"], ["2285.96", "2.301"], ["2286.63", "0.800"], ["2286.83", "15.270"], ["2286.84", "2.750"], ["2286.96", "9.727"], ["2287.39", "10.544"], ["2287.42", "143.365"]], "a": [["2287.77", "3.015"], ["2287.93", "20.234"], ["2288.04", "5.755"], ["2288.08", "3.485"], ["2288.16", "4.711"], ["2288.17", "4.170"], ["2288.31", "1.347"], ["2288.39", "24.059"], ["2288.40", "16.588"], ["2288.43", "17.740"], ["2288.54", "4.900"], ["2288.62", "1.811"], ["2288.63", "5.010"], ["2288.77", "9.982"], ["2288.85", "0.846"], ["2289.00", "8.324"], ["2289.03", "165.155"], ["2289.04", "0.121"], ["2289.08", "0.424"], ["2289.23", "2.476"], ["2289.24", "1.597"], ["2289.31", "26.964"], ["2289.46", "6.426"], ["2289.52", "12.515"], ["2289.53", "45.303"], ["2289.54", "2.042"], ["2289.68", "0.215"], ["2289.76", "0.024"], ["2289.77", "4.332"], ["2289.91", "2.296"], ["2289.99", "0.009"], ["2290.00", "19.868"], ["2290.14", "0.000"], ["2290.22", "2.208"], ["2290.23", "6.069"], ["2310.30", "5.764"], ["2401.79", "0.022"]]}
{"e": "depthUpdate", "E": 1703936454625, "T": 1703936454624, "s": "ETHUSDT", "U": 3743827187654, "u": 3743827191650, "pu": 3743827187474, "b": [["500.00", "184.422"], ["1000.00", "127.045"], ["2173.05", "0.043"], ["2264.55", "3.983"], ["2264.56", "0.057"], ["2275.98", "1.075"], ["2275.99", "0.043"], ["2277.14", "42.205"], ["2277.22", "0.000"], ["2282.30", "134.157"], ["2282.36", "0.000"], ["2283.41", "13.016"], ["2283.45", "0.000"], ["2283.47", "12.208"], ["2285.96", "1.998"], ["2285.98", "1.404"], ["2286.49", "17.493"], ["2286.52", "0.207"], ["2286.69", "23.109"], ["2286.71", "11.877"], ["2287.27", "0.790"], ["2287.30", "5.466"], ["2287.34", "0.000"], ["2287.40", "22.121"]], "a": [["2287.43", "16.712"], ["2287.64", "3.420"], ["2287.72", "0.000"], ["2287.77", "2.715"], ["2287.81", "1.906"], ["2288.09", "5.375"], ["2288.14", "23.253"], ["2288.15", "23.636"], ["2288.32", "0.215"], ["2288.33", "17.705"], ["2288.38", "11.361"], ["2288.55", "15.369"], ["2288.73", "2.221"], ["2288.78", "1.073"], ["2289.01", "4.572"], ["2289.23", "2.676"], ["2289.42", "11.489"], ["2289.46", "6.626"], ["2289.69", "0.220"], ["2289.88", "13.522"], ["2289.92", "24.003"], ["2290.15", "12.813"], ["2292.31", "0.614"], ["2292.32", "1.877"], ["2292.61", "18.885"], ["2292.69", "0.000"], ["2297.77", "42.422"], ["2297.84", "0.159"], ["2310.30", "2.810"], ["2333.87", "44.976"], ["2460.10", "0.030"]]}
{"e": "depthUpdate", "E": 1703936454728, "T": 1703936454727, "s": "ETHUSDT", "U": 3743827191793, "u": 3743827195808, "pu": 3743827191650, "b": [["500.00", "184.422"], ["2173.05", "0.043"], ["2251.81", "5.568"], ["2264.55", "3.983"], ["2266.85", "0.590"], ["2283.41", "23.016"], ["2283.45", "36.000"], ["2283.47", "48.208"], ["2284.82", "0.628"], ["2284.84", "0.847"], ["2284.85", "0.991"], ["2285.05", "0.200"], ["2285.07", "29.932"], ["2285.08", "14.874"], ["2285.21", "0.246"], ["2285.28", "12.931"], ["2285.30", "25.765"], ["2285.31", "46.834"], ["2285.51", "10.641"], ["2285.53", "0.610"], ["2285.74", "43.515"], ["2285.76", "9.411"], ["2285.96", "2.080"], ["2285.98", "1.604"], ["2285.99", "10.516"], ["2286.19", "0.400"], ["2286.21", "15.600"], ["2286.22", "3.604"], ["2286.42", "0.400"], ["2286.44", "19.388"], ["2286.45", "51.477"], ["2286.65", "18.774"], ["2286.67", "18.838"], ["2286.68", "14.300"], ["2286.69", "23.321"], ["2286.77", "3.882"], ["2286.88", "18.342"], ["2286.90", "0.430"], ["2286.91", "5.032"], ["2287.01", "5.332"], ["2287.02", "1.000"], ["2287.03", "3.563"], ["2287.04", "4.060"], ["2287.42", "143.377"]], "a": [["2287.43", "17.712"], ["2287.60", "0.009"], ["2287.77", "3.011"], ["2288.44", "23.589"], ["2292.31", "10.614"], ["2292.32", "73.877"], ["2310.30", "5.764"]]}
{"e": "depthUpdate", "E": 1703936454831, "T": 1703936454830, "s": "ETHUSDT", "U": 3743827195852, "u": 3743827198684, "pu": 3743827195808, "b": [["500.00", "184.422"], ["1000.00", "127.045"], ["1143.71", "0.000"], ["2012.92", "0.132"], ["2012.93", "0.055"], ["2165.45", "0.274"], ["2195.65", "0.010"], ["2225.84", "0.274"], ["2264.55", "3.983"], ["2266.85", "0.599"], ["2284.87", "1.939"], ["2285.10", "0.429"], ["2285.33", "15.955"], ["2285.55", "1.300"], ["2285.78", "2.019"], ["2285.96", "2.080"], ["2286.01", "24.241"], ["2286.24", "8.177"], ["2286.47", "14.759"], ["2286.69", "1.456"], ["2286.70", "19.379"], ["2286.71", "33.742"], ["2286.93", "7.026"]], "a": [["2287.77", "3.061"], ["2288.59", "19.196"], ["2288.63", "4.910"], ["2310.30", "2.810"], ["2333.18", "19.752"], ["2348.76", "1.110"], ["2348.78", "0.027"], ["2378.96", "1.934"], ["2378.97", "0.968"], ["2409.15", "1.162"], ["2409.17", "0.101"]]}
{"e": "depthUpdate", "E": 1703936454935, "T": 1703936454928, "s": "ETHUSDT", "U": 3743827198798, "u": 3743827201495, "pu": 3743827198684, "b": [["500.00", "184.422"], ["2173.05", "0.000"], ["2195.93", "0.000"], ["2264.55", "3.983"], ["2266.68", "0.018"], ["2285.25", "15.370"], ["2285.96", "2.080"], ["2286.26", "6.178"], ["2287.07", "0.000"], ["2287.42", "143.377"]], "a": [["2287.63", "8.442"], ["2287.73", "31.509"], ["2287.77", "2.715"], ["2287.82", "0.132"], ["2287.93", "20.234"], ["2289.02", "184.958"], ["2289.03", "4.231"], ["2290.06", "0.656"], ["2295.81", "10.000"], ["2310.30", "2.810"]]}
{"e": "depthUpdate", "E": 1703936455039, "T": 1703936455038, "s": "ETHUSDT", "U": 3743827201749, "u": 3743827205249, "pu": 3743827201495, "b": [["500.00", "184.422"], ["1000.00", "127.045"], ["2173.05", "0.043"], ["2173.06", "0.200"], ["2264.55", "1.961"], ["2264.56", "0.057"], ["2275.98", "1.075"], ["2285.13", "0.706"], ["2285.25", "81.008"], ["2285.94", "1.500"], ["2285.96", "2.080"], ["2286.15", "12.237"]], "a": [["2287.63", "14.442"], ["2287.64", "3.420"], ["2287.68", "18.903"], ["2287.70", "13.445"], ["2287.77", "3.116"], ["2288.24", "21.175"], ["2288.26", "8.292"], ["2288.64", "30.218"], ["2289.72", "0.350"], ["2290.05", "66.391"], ["2310.30", "11.708"], ["2401.79", "0.222"]]}
{"e": "depthUpdate", "E": 1703936455142, "T": 1703936455141, "s": "ETHUSDT", "U": 3743827205342, "u": 3743827208259, "pu": 3743827205249, "b": [["500.00", "184.422"], ["1000.00", "127.045"], ["2264.55", "7.006"], ["2283.41", "13.016"], ["2283.45", "0.000"], ["2283.47", "12.208"], ["2284.15", "15.886"], ["2284.16", "68.314"], ["2285.25", "81.008"], ["2285.41", "4.021"], ["2285.96", "2.080"], ["2286.39", "15.002"], ["2286.71", "33.732"], ["2286.73", "1.676"], ["2287.42", "143.368"]], "a": [["2287.43", "17.823"], ["2287.69", "10.861"], ["2287.70", "11.445"], ["2287.77", "3.139"], ["2289.41", "15.370"], ["2290.05", "0.890"], ["2290.39", "93.771"], ["2290.40", "2.792"], ["2291.65", "2.960"], ["2291.66", "4.643"], ["2292.31", "0.614"], ["2292.32", "1.877"], ["2310.30", "6.711"]]}
{"e": "depthUpdate", "E": 1703936455243, "T": 1703936455238, "s": "ETHUSDT", "U": 3743827208272, "u": 3743827211039, "pu": 3743827208259, "b": [["500.00", "184.422"], ["2058.68", "0.099"], ["2173.05", "0.043"], ["2218.79", "0.036"], ["2264.55", "0.082"], ["2264.56", "1.092"], ["2275.98", "0.040"], ["2283.41", "23.016"], ["2283.45", "36.000"], ["2283.47", "48.208"], ["2285.25", "81.008"], ["2285.96", "2.080"], ["2286.68", "15.174"], ["2286.70", "20.472"], ["2286.73", "0.802"], ["2286.74", "0.000"], ["2286.80", "1.485"], ["2286.82", "10.755"], ["2286.84", "3.406"], ["2287.42", "143.554"]], "a": [["2287.43", "17.743"], ["2287.60", "0.009"], ["2287.61", "2.186"], ["2287.62", "8.525"], ["2287.63", "0.000"], ["2287.68", "15.042"], ["2287.69", "8.861"], ["2287.73", "12.804"], ["2287.77", "2.715"], ["2287.82", "21.007"], ["2287.93", "20.234"], ["2288.74", "1.282"], ["2288.78", "0.200"], ["2288.89", "2.092"], ["2288.94", "1.825"], ["2289.44", "3.554"], ["2290.05", "66.391"], ["2291.33", "0.000"], ["2292.08", "7.118"], ["2292.30", "22.370"], ["2292.32", "73.877"], ["2293.97", "18.833"], ["2302.22", "1.025"], ["2302.74", "3.668"], ["2310.30", "10.633"]]}
{"e": "depthUpdate", "E": 1703936455345, "T": 1703936455344, "s": "ETHUSDT", "U": 3743827211133, "u": 3743827213980, "pu": 3743827211039, "b": [["500.00", "184.422"], ["1000.00", "127.045"], ["1143.71", "0.000"], ["2173.05", "0.000"], ["2218.79", "0.000"], ["2242.20", "113.614"], ["2264.55", "0.082"], ["2264.56", "0.057"], ["2266.69", "67.110"], ["2266.70", "1.096"], ["2284.78", "0.400"], ["2285.01", "45.529"], ["2285.22", "8.661"], ["2285.24", "6.377"], ["2285.45", "20.560"], ["2285.47", "7.515"], ["2285.67", "25.030"], ["2285.69", "1.996"], ["2285.90", "1.123"], ["2285.92", "17.306"], ["2285.96", "2.080"], ["2286.13", "14.790"], ["2286.15", "12.437"], ["2286.36", "0.835"], ["2286.38", "0.719"], ["2286.59", "1.014"], ["2286.61", "9.368"], ["2286.80", "1.220"], ["2286.82", "10.820"], ["2286.84", "3.606"], ["2287.42", "143.947"]], "a": [["2287.43", "17.876"], ["2287.62", "2.525"], ["2287.63", "8.702"], ["2287.66", "6.000"], ["2287.77", "3.162"], ["2288.24", "21.001"], ["2288.26", "8.466"], ["2289.24", "1.597"], ["2290.00", "27.247"], ["2293.97", "11.003"], ["2310.30", "13.587"], ["2352.60", "0.000"]]}
{"e": "depthUpdate", "E": 1703936455446, "T": 1703936455442, "s": "ETHUSDT", "U": 3743827213996, "u": 3743827216663, "pu": 3743827213980, "b": [["500.00", "184.422"], ["2264.55", "0.082"], ["2266.70", "0.061"], ["2275.98", "1.075"], ["2278.01", "0.665"], ["2280.28", "0.058"], ["2282.55", "1.682"], ["2285.25", "15.370"], ["2285.30", "2.485"], ["2285.32", "15.505"], ["2285.96", "1.798"], ["2287.42", "143.947"]], "a": [["2287.43", "17.872"], ["2287.77", "3.129"], ["2287.81", "14.297"], ["2287.82", "0.132"], ["2287.87", "20.986"], ["2287.89", "10.432"], ["2290.04", "0.259"], ["2290.05", "0.890"], ["2291.73", "40.016"], ["2294.01", "0.000"], ["2296.26", "0.237"], ["2310.30", "13.587"], ["2378.92", "0.000"], ["2401.79", "0.265"]]}
{"e": "depthUpdate", "E": 1703936455547, "T": 1703936455545, "s": "ETHUSDT", "U": 3743827216729, "u": 3743827219498, "pu": 3743827216663, "b": [["500.00", "184.422"], ["1000.00", "127.045"], ["2215.19", "0.770"], ["2215.20", "5.349"], ["2233.32", "0.698"], ["2251.42", "0.703"], ["2251.44", "5.716"], ["2264.55", "5.862"], ["2278.01", "0.938"], ["2280.28", "0.331"], ["2284.77", "0.022"], ["2285.00", "53.484"], ["2285.23", "11.701"], ["2285.25", "81.008"], ["2285.27", "6.208"], ["2285.28", "12.531"], ["2285.31", "47.234"], ["2285.32", "15.905"], ["2285.46", "0.065"], ["2285.69", "1.796"], ["2285.91", "1.674"], ["2285.96", "2.080"], ["2286.14", "5.428"], ["2286.37", "1.023"], ["2286.60", "4.324"], ["2286.83", "15.070"], ["2287.42", "145.491"]], "a": [["2287.77", "2.715"], ["2287.93", "20.234"], ["2288.48", "31.717"], ["2288.76", "25.815"], ["2288.77", "0.782"], ["2288.79", "0.796"], ["2288.80", "4.539"], ["2290.05", "66.391"], ["2291.92", "3.611"], ["2294.19", "3.049"], ["2296.44", "0.821"], ["2310.30", "7.807"], ["2323.74", "1.009"], ["2341.86", "5.941"], ["2352.62", "8.490"], ["2359.97", "0.698"], ["2401.79", "0.222"]]}
{"e": "depthUpdate", "E": 1703936455659, "T": 1703936455650, "s": "ETHUSDT", "U": 3743827219986, "u": 3743827222471, "pu": 3743827219498, "b": [["500.00", "184.422"], ["2239.63", "15.028"], ["2264.55", "5.862"], ["2266.69", "68.829"], ["2284.61", "4.789"], ["2284.65", "7.548"], ["2284.79", "0.212"], ["2284.84", "0.647"], ["2284.86", "1.209"], ["2285.02", "10.486"], ["2285.07", "29.732"], ["2285.09", "5.396"], ["2285.25", "81.208"], ["2285.30", "2.285"], ["2285.32", "16.105"], ["2285.48", "11.874"], ["2285.53", "0.410"], ["2285.55", "1.500"], ["2285.71", "1.426"], ["2285.76", "9.211"], ["2285.78", "2.219"], ["2285.93", "14.502"], ["2285.96", "2.080"], ["2285.99", "10.316"], ["2286.01", "24.441"], ["2286.16", "31.875"], ["2286.21", "15.400"], ["2286.23", "8.944"], ["2286.39", "15.202"], ["2286.44", "19.188"], ["2286.46", "44.129"], ["2286.62", "9.752"], ["2286.67", "18.638"], ["2286.69", "1.656"], ["2286.71", "11.867"], ["2286.72", "30.651"], ["2286.73", "2.114"], ["2286.85", "6.072"], ["2286.90", "0.230"], ["2286.92", "1.903"]], "a": [["2287.77", "3.108"], ["2287.89", "10.412"], ["2288.14", "23.053"], ["2288.15", "23.436"], ["2288.16", "4.931"], ["2288.17", "4.370"], ["2288.37", "0.720"], ["2288.39", "24.459"], ["2288.60", "4.627"], ["2288.62", "2.211"], ["2288.83", "52.126"], ["2288.85", "1.246"], ["2289.05", "2.379"], ["2289.06", "0.200"], ["2289.07", "4.207"], ["2289.08", "0.624"], ["2289.28", "1.071"], ["2289.29", "0.200"], ["2289.30", "6.114"], ["2289.31", "27.164"], ["2289.37", "6.826"], ["2289.39", "0.000"], ["2289.43", "5.407"], ["2289.51", "0.400"], ["2289.52", "12.315"], ["2289.53", "45.503"], ["2289.54", "2.242"], ["2289.74", "20.231"], ["2289.75", "0.853"], ["2289.76", "0.224"], ["2289.77", "4.532"], ["2289.97", "0.400"], ["2289.98", "0.812"], ["2289.99", "0.209"], ["2290.00", "27.447"], ["2290.05", "66.391"], ["2290.20", "1.056"], ["2290.21", "0.800"], ["2290.22", "2.408"], ["2290.23", "6.269"], ["2290.64", "0.468"], ["2290.68", "0.159"], ["2290.69", "0.000"], ["2298.91", "0.936"], ["2310.29", "3.175"], ["2310.30", "7.807"], ["2802.05", "0.159"]]}
{"e": "depthUpdate", "E": 1703936455765, "T": 1703936455764, "s": "ETHUSDT", "U": 3743827222725, "u": 3743827225477, "pu": 3743827222471, "b": [["500.00", "184.422"], ["1000.00", "127.045"], ["1944.48", "0.122"], ["2264.55", "0.082"], ["2266.67", "0.654"], ["2276.08", "0.000"], ["2281.80", "30.089"], ["2281.83", "41.496"], ["2283.41", "23.016"], ["2283.45", "36.000"], ["2283.47", "48.208"], ["2284.41", "17.742"], ["2284.70", "119.663"], ["2285.37", "2.909"], ["2285.89", "5.018"], ["2285.90", "75.492"], ["2285.91", "25.509"], ["2285.96", "2.080"], ["2286.49", "0.000"], ["2286.52", "17.700"], ["2286.72", "37.209"], ["2287.07", "3.279"], ["2287.42", "145.508"]], "a": [["2287.43", "12.863"], ["2287.61", "0.000"], ["2287.62", "0.000"], ["2287.63", "0.000"], ["2287.65", "0.000"], ["2287.66", "0.000"], ["2287.67", "0.024"], ["2287.68", "11.081"], ["2287.77", "2.991"], ["2287.96", "5.551"], ["2288.04", "5.667"], ["2288.06", "23.822"], ["2288.07", "19.291"], ["2288.08", "3.685"], ["2288.14", "1.202"], ["2288.15", "45.087"], ["2288.16", "4.911"], ["2288.17", "4.570"], ["2288.26", "8.292"], ["2288.28", "11.835"], ["2288.29", "19.070"], ["2288.30", "3.591"], ["2288.31", "1.521"], ["2288.34", "35.912"], ["2288.37", "0.720"], ["2288.38", "11.161"], ["2288.40", "16.788"], ["2288.43", "11.594"], ["2288.48", "37.863"], ["2288.51", "0.209"], ["2288.53", "1.019"], ["2288.59", "19.096"], ["2288.61", "0.600"], ["2288.63", "5.110"], ["2288.66", "0.227"], ["2288.74", "1.082"], ["2288.76", "26.015"], ["2288.80", "4.639"], ["2288.84", "0.615"], ["2288.86", "3.989"], ["2288.97", "0.439"], ["2288.99", "55.403"], ["2289.07", "4.007"], ["2289.09", "4.909"], ["2289.20", "2.936"], ["2289.22", "15.596"], ["2289.24", "8.865"], ["2289.30", "5.914"], ["2289.32", "0.961"], ["2289.38", "0.936"], ["2289.43", "5.207"], ["2289.45", "0.496"], ["2289.52", "12.115"], ["2289.54", "2.442"], ["2289.57", "5.044"], ["2289.58", "74.459"], ["2289.66", "0.200"], ["2289.68", "0.415"], ["2289.75", "0.653"], ["2289.77", "4.732"], ["2289.89", "1.731"], ["2289.91", "2.496"], ["2289.98", "0.612"], ["2290.00", "27.647"], ["2290.04", "19.572"], ["2290.12", "1.470"], ["2290.14", "0.200"], ["2290.21", "0.600"], ["2290.23", "6.469"], ["2290.28", "1.368"], ["2290.49", "0.180"], ["2290.63", "0.710"], ["2290.80", "125.832"], ["2292.08", "0.000"], ["2292.30", "22.370"], ["2292.32", "73.877"], ["2292.99", "0.411"], ["2293.02", "40.000"], ["2298.71", "0.013"], ["2298.86", "0.089"], ["2310.28", "1.496"], ["2310.29", "2.210"], ["2310.30", "0.931"], ["2401.79", "0.222"]]}
{"e": "depthUpdate", "E": 1703936455867, "T": 1703936455867, "s": "ETHUSDT", "U": 3743827225503, "u": 3743827228311, "pu": 3743827225477, "b": [["500.00", "184.422"], ["1000.00", "127.045"], ["2012.93", "0.055"], ["2195.93", "0.000"], ["2264.55", "3.036"], ["2276.11", "40.000"], ["2284.85", "0.791"], ["2284.86", "1.009"], ["2284.87", "2.139"], ["2284.88", "5.694"], ["2285.08", "14.474"], ["2285.10", "0.829"], ["2285.31", "46.834"], ["2285.33", "16.355"], ["2285.54", "26.676"], ["2285.56", "0.615"], ["2285.77", "31.330"], ["2285.79", "1.953"], ["2285.96", "2.080"], ["2285.99", "10.116"], ["2286.00", "44.379"], ["2286.01", "24.641"], ["2286.02", "0.400"], ["2286.22", "3.404"], ["2286.23", "8.744"], ["2286.24", "8.377"], ["2286.25", "0.585"], ["2286.45", "51.277"], ["2286.46", "43.929"], ["2286.47", "14.959"], ["2286.48", "2.879"], ["2286.68", "14.974"], ["2286.69", "1.456"], ["2286.70", "20.672"], ["2286.71", "12.067"], ["2286.91", "4.632"], ["2286.92", "6.081"], ["2286.93", "3.247"]], "a": [["2287.63", "1.553"], ["2287.67", "5.327"], ["2287.68", "5.081"], ["2287.69", "6.271"], ["2287.77", "2.715"], ["2287.89", "10.432"], ["2288.04", "5.647"], ["2288.15", "23.236"], ["2288.17", "26.421"], ["2288.19", "0.156"], ["2288.21", "22.328"], ["2288.32", "4.394"], ["2288.34", "31.734"], ["2288.35", "55.962"], ["2288.42", "21.715"], ["2288.44", "23.789"], ["2288.46", "31.636"], ["2288.48", "31.717"], ["2288.65", "0.000"], ["2288.67", "1.727"], ["2288.88", "90.398"], ["2288.90", "11.594"], ["2288.99", "8.725"], ["2289.02", "23.574"], ["2289.05", "164.190"], ["2289.11", "6.673"], ["2289.13", "1.220"], ["2289.33", "14.800"], ["2289.35", "1.020"], ["2289.56", "0.259"], ["2289.58", "74.659"], ["2289.79", "5.000"], ["2289.81", "1.105"], ["2290.02", "0.194"], ["2290.04", "19.772"], ["2290.25", "9.668"], ["2290.27", "0.574"], ["2290.64", "2.913"], ["2291.43", "0.028"], ["2298.74", "80.458"], ["2310.30", "6.732"], ["3129.15", "0.341"]]}
{"e": "depthUpdate", "E": 1703936455975, "T": 1703936455966, "s": "ETHUSDT", "U": 3743827228396, "u": 3743827230120, "pu": 3743827228311, "b": [["500.00", "184.422"], ["2213.83", "0.011"], ["2264.55", "3.036"], ["2264.56", "0.057"], ["2275.98", "0.040"], ["2275.99", "1.078"], ["2285.96", "1.798"], ["2286.72", "30.651"], ["2287.07", "0.000"]], "a": [["2287.66", "8.546"], ["2287.67", "0.024"], ["2287.77", "2.951"], ["2289.04", "162.609"], ["2289.05", "2.379"], ["2298.90", "1.519"], ["2310.28", "0.510"], ["2310.29", "2.231"], ["2310.30", "6.732"], ["2341.49", "0.045"]]}
{"e": "depthUpdate", "E": 1703936456085, "T": 1703936456079, "s": "ETHUSDT", "U": 3743827230334, "u": 3743827233056, "pu": 3743827230120, "b": [["500.00", "184.422"], ["1000.00", "127.045"], ["2173.05", "0.043"], ["2218.37", "0.519"], ["2264.55", "4.004"], ["2266.67", "2.373"], ["2284.82", "0.428"], ["2284.84", "0.847"], ["2285.04", "1.706"], ["2285.06", "38.793"], ["2285.13", "0.706"], ["2285.27", "6.008"], ["2285.29", "36.210"], ["2285.50", "74.387"], ["2285.52", "1.015"], ["2285.73", "1.250"], ["2285.75", "1.405"], ["2285.96", "1.598"], ["2285.98", "1.804"], ["2286.19", "0.200"], ["2286.21", "15.600"], ["2286.29", "2.318"], ["2286.30", "72.425"], ["2286.42", "0.200"], ["2286.44", "18.988"], ["2286.49", "17.493"], ["2286.52", "0.207"], ["2286.64", "0.015"], ["2286.66", "30.675"], ["2286.67", "19.038"], ["2286.87", "21.266"], ["2286.89", "6.283"]], "a": [["2287.43", "17.928"], ["2287.63", "2.534"], ["2287.66", "14.546"], ["2287.67", "8.696"], ["2287.68", "13.464"], ["2287.69", "0.271"], ["2287.72", "2.000"], ["2287.75", "0.018"], ["2287.77", "3.064"], ["2287.93", "20.234"], ["2288.15", "45.087"], ["2288.17", "4.570"], ["2288.28", "12.009"], ["2288.31", "1.347"], ["2288.80", "4.539"], ["2289.72", "0.350"], ["2298.90", "0.554"], ["2310.29", "3.196"], ["2310.30", "0.931"]]}
{"e": "depthUpdate", "E": 1703936456187, "T": 1703936456177, "s": "ETHUSDT", "U": 3743827233277, "u": 3743827236524, "pu": 3743827233056, "b": [["500.00", "184.422"], ["2173.05", "0.000"], ["2213.54", "9.787"], ["2264.55", "4.004"]], "a": [["2287.63", "0.000"], ["2287.64", "8.885"], ["2287.65", "0.000"], ["2287.66", "0.000"], ["2287.67", "0.024"], ["2287.68", "11.081"], ["2287.69", "0.271"], ["2287.72", "0.000"], ["2287.75", "0.018"], ["2287.77", "5.181"], ["2288.14", "2.095"], ["2288.16", "5.111"], ["2288.27", "6.798"], ["2288.28", "11.835"], ["2288.30", "3.765"], ["2288.37", "0.520"], ["2288.39", "24.659"], ["2288.59", "19.196"], ["2288.60", "4.427"], ["2288.62", "2.411"], ["2288.83", "51.926"], ["2288.85", "1.446"], ["2289.06", "0.000"], ["2289.08", "0.824"], ["2289.28", "0.871"], ["2289.30", "6.114"], ["2289.51", "0.200"], ["2289.53", "45.703"], ["2289.74", "20.031"], ["2289.76", "0.424"], ["2289.97", "0.200"], ["2289.99", "0.409"], ["2290.20", "0.856"], ["2290.22", "2.608"], ["2298.86", "1.054"], ["2310.29", "2.231"], ["2310.30", "0.931"], ["2593.91", "0.545"]]}
{"e": "depthUpdate", "E": 1703936456293, "T": 1703936456292, "s": "ETHUSDT", "U": 3743827237132, "u": 3743827239955, "pu": 3743827236524, "b": [["500.00", "184.422"], ["1000.00", "127.045"], ["2058.68", "0.099"], ["2264.55", "4.004"], ["2282.17", "43.344"], ["2283.41", "23.016"], ["2283.45", "36.000"], ["2283.47", "48.208"], ["2284.64", "0.000"], ["2285.25", "81.063"], ["2285.30", "2.140"], ["2285.42", "62.052"], ["2285.85", "3.539"], ["2286.63", "1.674"], ["2286.64", "1.108"], ["2286.65", "18.917"], ["2286.68", "14.100"], ["2286.70", "19.579"], ["2287.42", "145.504"]], "a": [["2287.77", "4.715"], ["2288.68", "3.102"], ["2288.74", "0.209"], ["2288.83", "53.018"], ["2288.89", "1.000"], ["2289.03", "167.813"], ["2289.04", "0.121"], ["2292.29", "66.145"], ["2292.30", "48.370"], ["2292.31", "36.614"], ["2292.32", "1.877"], ["2292.64", "3.861"], ["2310.30", "4.853"], ["2341.18", "8.531"], ["2401.79", "0.265"]]}
{"e": "depthUpdate", "E": 1703936456396, "T": 1703936456392, "s": "ETHUSDT", "U": 3743827240017, "u": 3743827243111, "pu": 3743827239955, "b": [["500.00", "184.422"], ["1143.71", "0.000"], ["2173.05", "0.043"], ["2218.80", "4.647"], ["2264.55", "0.082"], ["2264.56", "1.092"], ["2275.99", "0.043"], ["2282.19", "41.197"], ["2284.82", "0.228"], ["2284.84", "1.047"], ["2285.05", "0.000"], ["2285.07", "29.932"], ["2285.25", "81.063"], ["2285.28", "12.331"], ["2285.30", "2.340"], ["2285.51", "10.441"], ["2285.53", "0.610"], ["2285.74", "43.315"], ["2285.76", "9.411"], ["2285.96", "1.398"], ["2285.98", "2.004"], ["2286.19", "0.000"], ["2286.21", "15.800"], ["2286.42", "0.000"], ["2286.44", "19.188"], ["2286.65", "18.717"], ["2286.67", "19.238"], ["2286.88", "18.142"], ["2286.90", "0.430"], ["2287.42", "145.621"]], "a": [["2287.63", "2.441"], ["2287.67", "14.367"], ["2287.68", "5.081"], ["2287.74", "0.000"], ["2287.76", "9.848"], ["2287.77", "3.126"], ["2287.81", "1.906"], ["2287.86", "0.000"], ["2287.87", "20.986"], ["2287.93", "20.234"], ["2287.96", "5.646"], ["2288.10", "26.986"], ["2288.14", "2.532"], ["2288.23", "48.757"], ["2288.50", "2.446"], ["2290.05", "0.890"], ["2290.06", "66.156"], ["2292.66", "41.810"], ["2310.30", "4.853"], ["2378.92", "0.000"], ["2401.79", "0.222"]]}
